[2022-09-11 21:37:38,603] {taskinstance.py:1159} INFO - Dependencies all met for <TaskInstance: tcc_dag.add-db-data manual__2022-09-11T21:37:31.451991+00:00 [queued]>
[2022-09-11 21:37:38,614] {taskinstance.py:1159} INFO - Dependencies all met for <TaskInstance: tcc_dag.add-db-data manual__2022-09-11T21:37:31.451991+00:00 [queued]>
[2022-09-11 21:37:38,615] {taskinstance.py:1356} INFO - 
--------------------------------------------------------------------------------
[2022-09-11 21:37:38,615] {taskinstance.py:1357} INFO - Starting attempt 1 of 1
[2022-09-11 21:37:38,616] {taskinstance.py:1358} INFO - 
--------------------------------------------------------------------------------
[2022-09-11 21:37:38,629] {taskinstance.py:1377} INFO - Executing <Task(PythonOperator): add-db-data> on 2022-09-11 21:37:31.451991+00:00
[2022-09-11 21:37:38,635] {standard_task_runner.py:52} INFO - Started process 3466 to run task
[2022-09-11 21:37:38,639] {standard_task_runner.py:79} INFO - Running: ['***', 'tasks', 'run', 'tcc_dag', 'add-db-data', 'manual__2022-09-11T21:37:31.451991+00:00', '--job-id', '564', '--raw', '--subdir', 'DAGS_FOLDER/.ipynb_checkpoints/tcc_dag-checkpoint.py', '--cfg-path', '/tmp/tmprdqo7u7t', '--error-file', '/tmp/tmpfen7zpag']
[2022-09-11 21:37:38,640] {standard_task_runner.py:80} INFO - Job 564: Subtask add-db-data
[2022-09-11 21:37:38,702] {task_command.py:369} INFO - Running <TaskInstance: tcc_dag.add-db-data manual__2022-09-11T21:37:31.451991+00:00 [running]> on host b6ddae3e9f9e
[2022-09-11 21:37:38,777] {taskinstance.py:1571} INFO - Exporting the following env vars:
AIRFLOW_CTX_DAG_OWNER=Michelle Mesquita
AIRFLOW_CTX_DAG_ID=tcc_dag
AIRFLOW_CTX_TASK_ID=add-db-data
AIRFLOW_CTX_EXECUTION_DATE=2022-09-11T21:37:31.451991+00:00
AIRFLOW_CTX_TRY_NUMBER=1
AIRFLOW_CTX_DAG_RUN_ID=manual__2022-09-11T21:37:31.451991+00:00
[2022-09-11 21:37:38,791] {logging_mixin.py:115} INFO - Connecting to the MySQL database...
[2022-09-11 21:37:38,794] {logging_mixin.py:115} INFO - 2003 (HY000): Can't connect to MySQL server on 'localhost:3308' (99)
[2022-09-11 21:37:38,802] {logging_mixin.py:115} INFO - Connecting to the MySQL database...
[2022-09-11 21:37:38,803] {logging_mixin.py:115} INFO - 2003 (HY000): Can't connect to MySQL server on 'localhost:3308' (99)
[2022-09-11 21:37:38,805] {taskinstance.py:1889} ERROR - Task failed with exception
Traceback (most recent call last):
  File "/home/airflow/.local/lib/python3.7/site-packages/airflow/operators/python.py", line 171, in execute
    return_value = self.execute_callable()
  File "/home/airflow/.local/lib/python3.7/site-packages/airflow/operators/python.py", line 189, in execute_callable
    return self.python_callable(*self.op_args, **self.op_kwargs)
  File "/opt/airflow/dags/.ipynb_checkpoints/tcc_dag-checkpoint.py", line 147, in add_db_data
    os.remove('./dags/*.csv')
FileNotFoundError: [Errno 2] No such file or directory: './dags/*.csv'
[2022-09-11 21:37:38,816] {taskinstance.py:1400} INFO - Marking task as FAILED. dag_id=tcc_dag, task_id=add-db-data, execution_date=20220911T213731, start_date=20220911T213738, end_date=20220911T213738
[2022-09-11 21:37:38,828] {standard_task_runner.py:97} ERROR - Failed to execute job 564 for task add-db-data ([Errno 2] No such file or directory: './dags/*.csv'; 3466)
[2022-09-11 21:37:38,855] {local_task_job.py:156} INFO - Task exited with return code 1
[2022-09-11 21:37:38,914] {local_task_job.py:273} INFO - 0 downstream tasks scheduled from follow-on schedule check
