[2022-09-11 06:55:53,409] {taskinstance.py:1159} INFO - Dependencies all met for <TaskInstance: tcc_dag.add-db-data manual__2022-09-11T06:55:45.213063+00:00 [queued]>
[2022-09-11 06:55:53,426] {taskinstance.py:1159} INFO - Dependencies all met for <TaskInstance: tcc_dag.add-db-data manual__2022-09-11T06:55:45.213063+00:00 [queued]>
[2022-09-11 06:55:53,427] {taskinstance.py:1356} INFO - 
--------------------------------------------------------------------------------
[2022-09-11 06:55:53,428] {taskinstance.py:1357} INFO - Starting attempt 1 of 1
[2022-09-11 06:55:53,429] {taskinstance.py:1358} INFO - 
--------------------------------------------------------------------------------
[2022-09-11 06:55:53,443] {taskinstance.py:1377} INFO - Executing <Task(PythonOperator): add-db-data> on 2022-09-11 06:55:45.213063+00:00
[2022-09-11 06:55:53,449] {standard_task_runner.py:52} INFO - Started process 13622 to run task
[2022-09-11 06:55:53,453] {standard_task_runner.py:79} INFO - Running: ['***', 'tasks', 'run', 'tcc_dag', 'add-db-data', 'manual__2022-09-11T06:55:45.213063+00:00', '--job-id', '505', '--raw', '--subdir', 'DAGS_FOLDER/tcc_dag.py', '--cfg-path', '/tmp/tmpst5k3lnf', '--error-file', '/tmp/tmpyc5c0eui']
[2022-09-11 06:55:53,455] {standard_task_runner.py:80} INFO - Job 505: Subtask add-db-data
[2022-09-11 06:55:53,520] {task_command.py:369} INFO - Running <TaskInstance: tcc_dag.add-db-data manual__2022-09-11T06:55:45.213063+00:00 [running]> on host b6ddae3e9f9e
[2022-09-11 06:55:53,607] {taskinstance.py:1571} INFO - Exporting the following env vars:
AIRFLOW_CTX_DAG_OWNER=Michelle Mesquita
AIRFLOW_CTX_DAG_ID=tcc_dag
AIRFLOW_CTX_TASK_ID=add-db-data
AIRFLOW_CTX_EXECUTION_DATE=2022-09-11T06:55:45.213063+00:00
AIRFLOW_CTX_TRY_NUMBER=1
AIRFLOW_CTX_DAG_RUN_ID=manual__2022-09-11T06:55:45.213063+00:00
[2022-09-11 06:55:53,624] {taskinstance.py:1889} ERROR - Task failed with exception
Traceback (most recent call last):
  File "/home/airflow/.local/lib/python3.7/site-packages/airflow/operators/python.py", line 171, in execute
    return_value = self.execute_callable()
  File "/home/airflow/.local/lib/python3.7/site-packages/airflow/operators/python.py", line 189, in execute_callable
    return self.python_callable(*self.op_args, **self.op_kwargs)
  File "/opt/airflow/dags/tcc_dag.py", line 93, in add_db_data
    os.system(f'python3 ./dags/db-data.py {query} {df_db}')
NameError: name 'df_db' is not defined
[2022-09-11 06:55:53,640] {taskinstance.py:1400} INFO - Marking task as FAILED. dag_id=tcc_dag, task_id=add-db-data, execution_date=20220911T065545, start_date=20220911T065553, end_date=20220911T065553
[2022-09-11 06:55:53,652] {standard_task_runner.py:97} ERROR - Failed to execute job 505 for task add-db-data (name 'df_db' is not defined; 13622)
[2022-09-11 06:55:53,708] {local_task_job.py:156} INFO - Task exited with return code 1
[2022-09-11 06:55:53,754] {local_task_job.py:273} INFO - 0 downstream tasks scheduled from follow-on schedule check
