[2022-09-12 00:48:31,318] {taskinstance.py:1159} INFO - Dependencies all met for <TaskInstance: tcc_dag.add-db-data manual__2022-09-12T00:48:19.719241+00:00 [queued]>
[2022-09-12 00:48:31,333] {taskinstance.py:1159} INFO - Dependencies all met for <TaskInstance: tcc_dag.add-db-data manual__2022-09-12T00:48:19.719241+00:00 [queued]>
[2022-09-12 00:48:31,334] {taskinstance.py:1356} INFO - 
--------------------------------------------------------------------------------
[2022-09-12 00:48:31,335] {taskinstance.py:1357} INFO - Starting attempt 1 of 1
[2022-09-12 00:48:31,336] {taskinstance.py:1358} INFO - 
--------------------------------------------------------------------------------
[2022-09-12 00:48:31,355] {taskinstance.py:1377} INFO - Executing <Task(PythonOperator): add-db-data> on 2022-09-12 00:48:19.719241+00:00
[2022-09-12 00:48:31,364] {standard_task_runner.py:52} INFO - Started process 10569 to run task
[2022-09-12 00:48:31,373] {standard_task_runner.py:79} INFO - Running: ['***', 'tasks', 'run', 'tcc_dag', 'add-db-data', 'manual__2022-09-12T00:48:19.719241+00:00', '--job-id', '587', '--raw', '--subdir', 'DAGS_FOLDER/.ipynb_checkpoints/tcc_dag-checkpoint.py', '--cfg-path', '/tmp/tmp1ho0b_g7', '--error-file', '/tmp/tmpj6a88917']
[2022-09-12 00:48:31,375] {standard_task_runner.py:80} INFO - Job 587: Subtask add-db-data
[2022-09-12 00:48:31,473] {task_command.py:369} INFO - Running <TaskInstance: tcc_dag.add-db-data manual__2022-09-12T00:48:19.719241+00:00 [running]> on host b6ddae3e9f9e
[2022-09-12 00:48:31,619] {taskinstance.py:1571} INFO - Exporting the following env vars:
AIRFLOW_CTX_DAG_OWNER=Michelle Mesquita
AIRFLOW_CTX_DAG_ID=tcc_dag
AIRFLOW_CTX_TASK_ID=add-db-data
AIRFLOW_CTX_EXECUTION_DATE=2022-09-12T00:48:19.719241+00:00
AIRFLOW_CTX_TRY_NUMBER=1
AIRFLOW_CTX_DAG_RUN_ID=manual__2022-09-12T00:48:19.719241+00:00
[2022-09-12 00:48:31,637] {logging_mixin.py:115} INFO - Connecting to the MySQL database...
[2022-09-12 00:48:31,640] {logging_mixin.py:115} INFO - 2003 (HY000): Can't connect to MySQL server on 'localhost:3308' (99)
[2022-09-12 00:48:31,649] {taskinstance.py:1889} ERROR - Task failed with exception
Traceback (most recent call last):
  File "/home/airflow/.local/lib/python3.7/site-packages/airflow/operators/python.py", line 171, in execute
    return_value = self.execute_callable()
  File "/home/airflow/.local/lib/python3.7/site-packages/airflow/operators/python.py", line 189, in execute_callable
    return self.python_callable(*self.op_args, **self.op_kwargs)
  File "/opt/airflow/dags/.ipynb_checkpoints/tcc_dag-checkpoint.py", line 117, in add_db_data
    df_diff1.index  = df_diff.index + len(df_db)
TypeError: object of type 'NoneType' has no len()
[2022-09-12 00:48:31,685] {taskinstance.py:1400} INFO - Marking task as FAILED. dag_id=tcc_dag, task_id=add-db-data, execution_date=20220912T004819, start_date=20220912T004831, end_date=20220912T004831
[2022-09-12 00:48:31,710] {standard_task_runner.py:97} ERROR - Failed to execute job 587 for task add-db-data (object of type 'NoneType' has no len(); 10569)
[2022-09-12 00:48:31,750] {local_task_job.py:156} INFO - Task exited with return code 1
[2022-09-12 00:48:31,812] {local_task_job.py:273} INFO - 0 downstream tasks scheduled from follow-on schedule check
