[2022-09-09 01:01:02,618] {taskinstance.py:1159} INFO - Dependencies all met for <TaskInstance: tcc_dag.gitlab-dast-data manual__2022-09-09T01:01:00.169498+00:00 [queued]>
[2022-09-09 01:01:02,645] {taskinstance.py:1159} INFO - Dependencies all met for <TaskInstance: tcc_dag.gitlab-dast-data manual__2022-09-09T01:01:00.169498+00:00 [queued]>
[2022-09-09 01:01:02,647] {taskinstance.py:1356} INFO - 
--------------------------------------------------------------------------------
[2022-09-09 01:01:02,648] {taskinstance.py:1357} INFO - Starting attempt 1 of 1
[2022-09-09 01:01:02,650] {taskinstance.py:1358} INFO - 
--------------------------------------------------------------------------------
[2022-09-09 01:01:02,697] {taskinstance.py:1377} INFO - Executing <Task(PythonOperator): gitlab-dast-data> on 2022-09-09 01:01:00.169498+00:00
[2022-09-09 01:01:02,713] {standard_task_runner.py:52} INFO - Started process 80 to run task
[2022-09-09 01:01:02,733] {standard_task_runner.py:79} INFO - Running: ['***', 'tasks', 'run', 'tcc_dag', 'gitlab-dast-data', 'manual__2022-09-09T01:01:00.169498+00:00', '--job-id', '200', '--raw', '--subdir', 'DAGS_FOLDER/.ipynb_checkpoints/tcc_dag-checkpoint.py', '--cfg-path', '/tmp/tmpmipozvgr', '--error-file', '/tmp/tmph4uy3eqy']
[2022-09-09 01:01:02,737] {standard_task_runner.py:80} INFO - Job 200: Subtask gitlab-dast-data
[2022-09-09 01:01:02,904] {task_command.py:369} INFO - Running <TaskInstance: tcc_dag.gitlab-dast-data manual__2022-09-09T01:01:00.169498+00:00 [running]> on host 9a5942a886e3
[2022-09-09 01:01:03,070] {taskinstance.py:1571} INFO - Exporting the following env vars:
AIRFLOW_CTX_DAG_OWNER=Michelle Mesquita
AIRFLOW_CTX_DAG_ID=tcc_dag
AIRFLOW_CTX_TASK_ID=gitlab-dast-data
AIRFLOW_CTX_EXECUTION_DATE=2022-09-09T01:01:00.169498+00:00
AIRFLOW_CTX_TRY_NUMBER=1
AIRFLOW_CTX_DAG_RUN_ID=manual__2022-09-09T01:01:00.169498+00:00
[2022-09-09 01:01:03,076] {taskinstance.py:1889} ERROR - Task failed with exception
Traceback (most recent call last):
  File "/home/airflow/.local/lib/python3.7/site-packages/airflow/operators/python.py", line 171, in execute
    return_value = self.execute_callable()
  File "/home/airflow/.local/lib/python3.7/site-packages/airflow/operators/python.py", line 189, in execute_callable
    return self.python_callable(*self.op_args, **self.op_kwargs)
  File "/opt/airflow/dags/.ipynb_checkpoints/tcc_dag-checkpoint.py", line 44, in get_gitlab_data
    for x in open("${AIRFLOW_HOME}/project_id_gitlab.txt", "r"):
FileNotFoundError: [Errno 2] No such file or directory: '${AIRFLOW_HOME}/project_id_gitlab.txt'
[2022-09-09 01:01:03,096] {taskinstance.py:1400} INFO - Marking task as FAILED. dag_id=tcc_dag, task_id=gitlab-dast-data, execution_date=20220909T010100, start_date=20220909T010102, end_date=20220909T010103
[2022-09-09 01:01:03,127] {standard_task_runner.py:97} ERROR - Failed to execute job 200 for task gitlab-dast-data ([Errno 2] No such file or directory: '${AIRFLOW_HOME}/project_id_gitlab.txt'; 80)
[2022-09-09 01:01:03,184] {local_task_job.py:156} INFO - Task exited with return code 1
[2022-09-09 01:01:03,285] {local_task_job.py:273} INFO - 0 downstream tasks scheduled from follow-on schedule check
