[2022-09-09 00:53:14,616] {taskinstance.py:1159} INFO - Dependencies all met for <TaskInstance: tcc_dag.snyk-sast-data manual__2022-09-09T00:53:12.768753+00:00 [queued]>
[2022-09-09 00:53:14,639] {taskinstance.py:1159} INFO - Dependencies all met for <TaskInstance: tcc_dag.snyk-sast-data manual__2022-09-09T00:53:12.768753+00:00 [queued]>
[2022-09-09 00:53:14,640] {taskinstance.py:1356} INFO - 
--------------------------------------------------------------------------------
[2022-09-09 00:53:14,641] {taskinstance.py:1357} INFO - Starting attempt 1 of 1
[2022-09-09 00:53:14,642] {taskinstance.py:1358} INFO - 
--------------------------------------------------------------------------------
[2022-09-09 00:53:14,664] {taskinstance.py:1377} INFO - Executing <Task(PythonOperator): snyk-sast-data> on 2022-09-09 00:53:12.768753+00:00
[2022-09-09 00:53:14,671] {standard_task_runner.py:52} INFO - Started process 77 to run task
[2022-09-09 00:53:14,689] {standard_task_runner.py:79} INFO - Running: ['***', 'tasks', 'run', 'tcc_dag', 'snyk-sast-data', 'manual__2022-09-09T00:53:12.768753+00:00', '--job-id', '133', '--raw', '--subdir', 'DAGS_FOLDER/.ipynb_checkpoints/tcc_dag-checkpoint.py', '--cfg-path', '/tmp/tmpb9pa9053', '--error-file', '/tmp/tmp8y2n1gux']
[2022-09-09 00:53:14,690] {standard_task_runner.py:80} INFO - Job 133: Subtask snyk-sast-data
[2022-09-09 00:53:14,960] {task_command.py:369} INFO - Running <TaskInstance: tcc_dag.snyk-sast-data manual__2022-09-09T00:53:12.768753+00:00 [running]> on host 9a5942a886e3
[2022-09-09 00:53:15,240] {taskinstance.py:1571} INFO - Exporting the following env vars:
AIRFLOW_CTX_DAG_OWNER=Michelle Mesquita
AIRFLOW_CTX_DAG_ID=tcc_dag
AIRFLOW_CTX_TASK_ID=snyk-sast-data
AIRFLOW_CTX_EXECUTION_DATE=2022-09-09T00:53:12.768753+00:00
AIRFLOW_CTX_TRY_NUMBER=1
AIRFLOW_CTX_DAG_RUN_ID=manual__2022-09-09T00:53:12.768753+00:00
[2022-09-09 00:53:15,258] {taskinstance.py:1889} ERROR - Task failed with exception
Traceback (most recent call last):
  File "/home/airflow/.local/lib/python3.7/site-packages/airflow/operators/python.py", line 171, in execute
    return_value = self.execute_callable()
  File "/home/airflow/.local/lib/python3.7/site-packages/airflow/operators/python.py", line 189, in execute_callable
    return self.python_callable(*self.op_args, **self.op_kwargs)
  File "/opt/airflow/dags/.ipynb_checkpoints/tcc_dag-checkpoint.py", line 28, in get_snyk_data
    for x in open("/usr/local/airflow/dags/project_id_snyk.txt", "r"):
FileNotFoundError: [Errno 2] No such file or directory: '/usr/local/airflow/dags/project_id_snyk.txt'
[2022-09-09 00:53:15,285] {taskinstance.py:1400} INFO - Marking task as FAILED. dag_id=tcc_dag, task_id=snyk-sast-data, execution_date=20220909T005312, start_date=20220909T005314, end_date=20220909T005315
[2022-09-09 00:53:15,323] {standard_task_runner.py:97} ERROR - Failed to execute job 133 for task snyk-sast-data ([Errno 2] No such file or directory: '/usr/local/airflow/dags/project_id_snyk.txt'; 77)
[2022-09-09 00:53:15,432] {local_task_job.py:156} INFO - Task exited with return code 1
[2022-09-09 00:53:15,507] {local_task_job.py:273} INFO - 0 downstream tasks scheduled from follow-on schedule check
