[2022-09-11 21:21:09,713] {taskinstance.py:1159} INFO - Dependencies all met for <TaskInstance: tcc_dag.add-db-data manual__2022-09-11T21:20:53.718634+00:00 [queued]>
[2022-09-11 21:21:09,735] {taskinstance.py:1159} INFO - Dependencies all met for <TaskInstance: tcc_dag.add-db-data manual__2022-09-11T21:20:53.718634+00:00 [queued]>
[2022-09-11 21:21:09,736] {taskinstance.py:1356} INFO - 
--------------------------------------------------------------------------------
[2022-09-11 21:21:09,737] {taskinstance.py:1357} INFO - Starting attempt 1 of 1
[2022-09-11 21:21:09,738] {taskinstance.py:1358} INFO - 
--------------------------------------------------------------------------------
[2022-09-11 21:21:09,754] {taskinstance.py:1377} INFO - Executing <Task(PythonOperator): add-db-data> on 2022-09-11 21:20:53.718634+00:00
[2022-09-11 21:21:09,760] {standard_task_runner.py:52} INFO - Started process 2255 to run task
[2022-09-11 21:21:09,765] {standard_task_runner.py:79} INFO - Running: ['***', 'tasks', 'run', 'tcc_dag', 'add-db-data', 'manual__2022-09-11T21:20:53.718634+00:00', '--job-id', '524', '--raw', '--subdir', 'DAGS_FOLDER/tcc_dag.py', '--cfg-path', '/tmp/tmp8y1voo5t', '--error-file', '/tmp/tmpgeb7_du3']
[2022-09-11 21:21:09,767] {standard_task_runner.py:80} INFO - Job 524: Subtask add-db-data
[2022-09-11 21:21:09,835] {task_command.py:369} INFO - Running <TaskInstance: tcc_dag.add-db-data manual__2022-09-11T21:20:53.718634+00:00 [running]> on host b6ddae3e9f9e
[2022-09-11 21:21:09,912] {taskinstance.py:1571} INFO - Exporting the following env vars:
AIRFLOW_CTX_DAG_OWNER=Michelle Mesquita
AIRFLOW_CTX_DAG_ID=tcc_dag
AIRFLOW_CTX_TASK_ID=add-db-data
AIRFLOW_CTX_EXECUTION_DATE=2022-09-11T21:20:53.718634+00:00
AIRFLOW_CTX_TRY_NUMBER=1
AIRFLOW_CTX_DAG_RUN_ID=manual__2022-09-11T21:20:53.718634+00:00
[2022-09-11 21:21:09,929] {logging_mixin.py:115} INFO - Connecting to the MySQL database...
[2022-09-11 21:21:09,933] {logging_mixin.py:115} INFO - 2003 (HY000): Can't connect to MySQL server on 'localhost:3308' (99)
[2022-09-11 21:21:09,948] {taskinstance.py:1889} ERROR - Task failed with exception
Traceback (most recent call last):
  File "/home/airflow/.local/lib/python3.7/site-packages/airflow/operators/python.py", line 171, in execute
    return_value = self.execute_callable()
  File "/home/airflow/.local/lib/python3.7/site-packages/airflow/operators/python.py", line 189, in execute_callable
    return self.python_callable(*self.op_args, **self.op_kwargs)
  File "/opt/airflow/dags/tcc_dag.py", line 117, in add_db_data
    df_diff1.index  = df_diff.index + len(df_db)
TypeError: object of type 'NoneType' has no len()
[2022-09-11 21:21:09,963] {taskinstance.py:1400} INFO - Marking task as FAILED. dag_id=tcc_dag, task_id=add-db-data, execution_date=20220911T212053, start_date=20220911T212109, end_date=20220911T212109
[2022-09-11 21:21:09,976] {standard_task_runner.py:97} ERROR - Failed to execute job 524 for task add-db-data (object of type 'NoneType' has no len(); 2255)
[2022-09-11 21:21:10,020] {local_task_job.py:156} INFO - Task exited with return code 1
[2022-09-11 21:21:10,064] {local_task_job.py:273} INFO - 0 downstream tasks scheduled from follow-on schedule check
