[2022-09-09 00:55:38,943] {taskinstance.py:1159} INFO - Dependencies all met for <TaskInstance: tcc_dag.snyk-sast-data manual__2022-09-09T00:55:36.951521+00:00 [queued]>
[2022-09-09 00:55:38,974] {taskinstance.py:1159} INFO - Dependencies all met for <TaskInstance: tcc_dag.snyk-sast-data manual__2022-09-09T00:55:36.951521+00:00 [queued]>
[2022-09-09 00:55:38,975] {taskinstance.py:1356} INFO - 
--------------------------------------------------------------------------------
[2022-09-09 00:55:38,977] {taskinstance.py:1357} INFO - Starting attempt 1 of 1
[2022-09-09 00:55:38,979] {taskinstance.py:1358} INFO - 
--------------------------------------------------------------------------------
[2022-09-09 00:55:39,005] {taskinstance.py:1377} INFO - Executing <Task(PythonOperator): snyk-sast-data> on 2022-09-09 00:55:36.951521+00:00
[2022-09-09 00:55:39,017] {standard_task_runner.py:52} INFO - Started process 208 to run task
[2022-09-09 00:55:39,024] {standard_task_runner.py:79} INFO - Running: ['***', 'tasks', 'run', 'tcc_dag', 'snyk-sast-data', 'manual__2022-09-09T00:55:36.951521+00:00', '--job-id', '136', '--raw', '--subdir', 'DAGS_FOLDER/.ipynb_checkpoints/tcc_dag-checkpoint.py', '--cfg-path', '/tmp/tmpdwrxt_7v', '--error-file', '/tmp/tmpmqsz_0z_']
[2022-09-09 00:55:39,027] {standard_task_runner.py:80} INFO - Job 136: Subtask snyk-sast-data
[2022-09-09 00:55:39,153] {task_command.py:369} INFO - Running <TaskInstance: tcc_dag.snyk-sast-data manual__2022-09-09T00:55:36.951521+00:00 [running]> on host 9a5942a886e3
[2022-09-09 00:55:39,326] {taskinstance.py:1571} INFO - Exporting the following env vars:
AIRFLOW_CTX_DAG_OWNER=Michelle Mesquita
AIRFLOW_CTX_DAG_ID=tcc_dag
AIRFLOW_CTX_TASK_ID=snyk-sast-data
AIRFLOW_CTX_EXECUTION_DATE=2022-09-09T00:55:36.951521+00:00
AIRFLOW_CTX_TRY_NUMBER=1
AIRFLOW_CTX_DAG_RUN_ID=manual__2022-09-09T00:55:36.951521+00:00
[2022-09-09 00:55:39,332] {taskinstance.py:1889} ERROR - Task failed with exception
Traceback (most recent call last):
  File "/home/airflow/.local/lib/python3.7/site-packages/airflow/operators/python.py", line 171, in execute
    return_value = self.execute_callable()
  File "/home/airflow/.local/lib/python3.7/site-packages/airflow/operators/python.py", line 189, in execute_callable
    return self.python_callable(*self.op_args, **self.op_kwargs)
  File "/opt/airflow/dags/.ipynb_checkpoints/tcc_dag-checkpoint.py", line 28, in get_snyk_data
    for x in open("project_id_snyk.txt", "r"):
FileNotFoundError: [Errno 2] No such file or directory: 'project_id_snyk.txt'
[2022-09-09 00:55:39,349] {taskinstance.py:1400} INFO - Marking task as FAILED. dag_id=tcc_dag, task_id=snyk-sast-data, execution_date=20220909T005536, start_date=20220909T005538, end_date=20220909T005539
[2022-09-09 00:55:39,367] {standard_task_runner.py:97} ERROR - Failed to execute job 136 for task snyk-sast-data ([Errno 2] No such file or directory: 'project_id_snyk.txt'; 208)
[2022-09-09 00:55:39,407] {local_task_job.py:156} INFO - Task exited with return code 1
[2022-09-09 00:55:39,472] {local_task_job.py:273} INFO - 0 downstream tasks scheduled from follow-on schedule check
