[2022-09-09 00:12:36,802] {taskinstance.py:1159} INFO - Dependencies all met for <TaskInstance: tcc_dag.snyk-sast-data scheduled__2022-09-08T00:00:00+00:00 [queued]>
[2022-09-09 00:12:36,899] {taskinstance.py:1159} INFO - Dependencies all met for <TaskInstance: tcc_dag.snyk-sast-data scheduled__2022-09-08T00:00:00+00:00 [queued]>
[2022-09-09 00:12:36,902] {taskinstance.py:1356} INFO - 
--------------------------------------------------------------------------------
[2022-09-09 00:12:36,906] {taskinstance.py:1357} INFO - Starting attempt 1 of 1
[2022-09-09 00:12:36,907] {taskinstance.py:1358} INFO - 
--------------------------------------------------------------------------------
[2022-09-09 00:12:37,067] {taskinstance.py:1377} INFO - Executing <Task(PythonOperator): snyk-sast-data> on 2022-09-08 00:00:00+00:00
[2022-09-09 00:12:37,167] {standard_task_runner.py:52} INFO - Started process 177 to run task
[2022-09-09 00:12:37,260] {standard_task_runner.py:79} INFO - Running: ['***', 'tasks', 'run', 'tcc_dag', 'snyk-sast-data', 'scheduled__2022-09-08T00:00:00+00:00', '--job-id', '130', '--raw', '--subdir', 'DAGS_FOLDER/.ipynb_checkpoints/tcc_dag-checkpoint.py', '--cfg-path', '/tmp/tmpiopzeelz', '--error-file', '/tmp/tmpkncqp_wr']
[2022-09-09 00:12:37,272] {standard_task_runner.py:80} INFO - Job 130: Subtask snyk-sast-data
[2022-09-09 00:12:38,057] {task_command.py:369} INFO - Running <TaskInstance: tcc_dag.snyk-sast-data scheduled__2022-09-08T00:00:00+00:00 [running]> on host 9a5942a886e3
[2022-09-09 00:12:38,568] {taskinstance.py:1571} INFO - Exporting the following env vars:
AIRFLOW_CTX_DAG_OWNER=Michelle Mesquita
AIRFLOW_CTX_DAG_ID=tcc_dag
AIRFLOW_CTX_TASK_ID=snyk-sast-data
AIRFLOW_CTX_EXECUTION_DATE=2022-09-08T00:00:00+00:00
AIRFLOW_CTX_TRY_NUMBER=1
AIRFLOW_CTX_DAG_RUN_ID=scheduled__2022-09-08T00:00:00+00:00
[2022-09-09 00:12:38,586] {taskinstance.py:1889} ERROR - Task failed with exception
Traceback (most recent call last):
  File "/home/airflow/.local/lib/python3.7/site-packages/airflow/operators/python.py", line 171, in execute
    return_value = self.execute_callable()
  File "/home/airflow/.local/lib/python3.7/site-packages/airflow/operators/python.py", line 189, in execute_callable
    return self.python_callable(*self.op_args, **self.op_kwargs)
  File "/opt/airflow/dags/.ipynb_checkpoints/tcc_dag-checkpoint.py", line 28, in get_snyk_data
    for x in open("/Users/mac/Desktop/TCC-IGTI/airflow-local/dags/project_id_snyk.txt", "r"):
FileNotFoundError: [Errno 2] No such file or directory: '/Users/mac/Desktop/TCC-IGTI/airflow-local/dags/project_id_snyk.txt'
[2022-09-09 00:12:38,770] {taskinstance.py:1400} INFO - Marking task as FAILED. dag_id=tcc_dag, task_id=snyk-sast-data, execution_date=20220908T000000, start_date=20220909T001236, end_date=20220909T001238
[2022-09-09 00:12:38,880] {standard_task_runner.py:97} ERROR - Failed to execute job 130 for task snyk-sast-data ([Errno 2] No such file or directory: '/Users/mac/Desktop/TCC-IGTI/airflow-local/dags/project_id_snyk.txt'; 177)
[2022-09-09 00:12:38,986] {local_task_job.py:156} INFO - Task exited with return code 1
[2022-09-09 00:12:39,164] {local_task_job.py:273} INFO - 0 downstream tasks scheduled from follow-on schedule check
