[2022-09-12 03:30:34,784] {taskinstance.py:1159} INFO - Dependencies all met for <TaskInstance: tcc_dag.add-db-data manual__2022-09-12T03:30:24.745003+00:00 [queued]>
[2022-09-12 03:30:34,797] {taskinstance.py:1159} INFO - Dependencies all met for <TaskInstance: tcc_dag.add-db-data manual__2022-09-12T03:30:24.745003+00:00 [queued]>
[2022-09-12 03:30:34,798] {taskinstance.py:1356} INFO - 
--------------------------------------------------------------------------------
[2022-09-12 03:30:34,800] {taskinstance.py:1357} INFO - Starting attempt 1 of 1
[2022-09-12 03:30:34,800] {taskinstance.py:1358} INFO - 
--------------------------------------------------------------------------------
[2022-09-12 03:30:34,818] {taskinstance.py:1377} INFO - Executing <Task(PythonOperator): add-db-data> on 2022-09-12 03:30:24.745003+00:00
[2022-09-12 03:30:34,825] {standard_task_runner.py:52} INFO - Started process 19080 to run task
[2022-09-12 03:30:34,829] {standard_task_runner.py:79} INFO - Running: ['***', 'tasks', 'run', 'tcc_dag', 'add-db-data', 'manual__2022-09-12T03:30:24.745003+00:00', '--job-id', '617', '--raw', '--subdir', 'DAGS_FOLDER/.ipynb_checkpoints/tcc_dag-checkpoint.py', '--cfg-path', '/tmp/tmpt7t918fb', '--error-file', '/tmp/tmp_husm6e1']
[2022-09-12 03:30:34,831] {standard_task_runner.py:80} INFO - Job 617: Subtask add-db-data
[2022-09-12 03:30:34,906] {task_command.py:369} INFO - Running <TaskInstance: tcc_dag.add-db-data manual__2022-09-12T03:30:24.745003+00:00 [running]> on host b6ddae3e9f9e
[2022-09-12 03:30:35,006] {taskinstance.py:1571} INFO - Exporting the following env vars:
AIRFLOW_CTX_DAG_OWNER=Michelle Mesquita
AIRFLOW_CTX_DAG_ID=tcc_dag
AIRFLOW_CTX_TASK_ID=add-db-data
AIRFLOW_CTX_EXECUTION_DATE=2022-09-12T03:30:24.745003+00:00
AIRFLOW_CTX_TRY_NUMBER=1
AIRFLOW_CTX_DAG_RUN_ID=manual__2022-09-12T03:30:24.745003+00:00
[2022-09-12 03:30:35,023] {logging_mixin.py:115} INFO - Connecting to the MySQL database...
[2022-09-12 03:30:35,026] {logging_mixin.py:115} INFO - 2003 (HY000): Can't connect to MySQL server on 'localhost:3308' (99)
[2022-09-12 03:30:35,033] {taskinstance.py:1889} ERROR - Task failed with exception
Traceback (most recent call last):
  File "/home/airflow/.local/lib/python3.7/site-packages/airflow/operators/python.py", line 171, in execute
    return_value = self.execute_callable()
  File "/home/airflow/.local/lib/python3.7/site-packages/airflow/operators/python.py", line 189, in execute_callable
    return self.python_callable(*self.op_args, **self.op_kwargs)
  File "/opt/airflow/dags/.ipynb_checkpoints/tcc_dag-checkpoint.py", line 116, in add_db_data
    display(df_current.head())
NameError: name 'display' is not defined
[2022-09-12 03:30:35,046] {taskinstance.py:1400} INFO - Marking task as FAILED. dag_id=tcc_dag, task_id=add-db-data, execution_date=20220912T033024, start_date=20220912T033034, end_date=20220912T033035
[2022-09-12 03:30:35,061] {standard_task_runner.py:97} ERROR - Failed to execute job 617 for task add-db-data (name 'display' is not defined; 19080)
[2022-09-12 03:30:35,086] {local_task_job.py:156} INFO - Task exited with return code 1
[2022-09-12 03:30:35,148] {local_task_job.py:273} INFO - 0 downstream tasks scheduled from follow-on schedule check
