[2022-09-09 00:53:14,678] {taskinstance.py:1159} INFO - Dependencies all met for <TaskInstance: tcc_dag.github-sca-data manual__2022-09-09T00:53:12.768753+00:00 [queued]>
[2022-09-09 00:53:14,693] {taskinstance.py:1159} INFO - Dependencies all met for <TaskInstance: tcc_dag.github-sca-data manual__2022-09-09T00:53:12.768753+00:00 [queued]>
[2022-09-09 00:53:14,695] {taskinstance.py:1356} INFO - 
--------------------------------------------------------------------------------
[2022-09-09 00:53:14,696] {taskinstance.py:1357} INFO - Starting attempt 1 of 1
[2022-09-09 00:53:14,696] {taskinstance.py:1358} INFO - 
--------------------------------------------------------------------------------
[2022-09-09 00:53:14,730] {taskinstance.py:1377} INFO - Executing <Task(PythonOperator): github-sca-data> on 2022-09-09 00:53:12.768753+00:00
[2022-09-09 00:53:14,745] {standard_task_runner.py:52} INFO - Started process 78 to run task
[2022-09-09 00:53:14,763] {standard_task_runner.py:79} INFO - Running: ['***', 'tasks', 'run', 'tcc_dag', 'github-sca-data', 'manual__2022-09-09T00:53:12.768753+00:00', '--job-id', '134', '--raw', '--subdir', 'DAGS_FOLDER/.ipynb_checkpoints/tcc_dag-checkpoint.py', '--cfg-path', '/tmp/tmp9ozdvusq', '--error-file', '/tmp/tmpgybrb5yc']
[2022-09-09 00:53:14,768] {standard_task_runner.py:80} INFO - Job 134: Subtask github-sca-data
[2022-09-09 00:53:15,184] {task_command.py:369} INFO - Running <TaskInstance: tcc_dag.github-sca-data manual__2022-09-09T00:53:12.768753+00:00 [running]> on host 9a5942a886e3
[2022-09-09 00:53:15,408] {taskinstance.py:1571} INFO - Exporting the following env vars:
AIRFLOW_CTX_DAG_OWNER=Michelle Mesquita
AIRFLOW_CTX_DAG_ID=tcc_dag
AIRFLOW_CTX_TASK_ID=github-sca-data
AIRFLOW_CTX_EXECUTION_DATE=2022-09-09T00:53:12.768753+00:00
AIRFLOW_CTX_TRY_NUMBER=1
AIRFLOW_CTX_DAG_RUN_ID=manual__2022-09-09T00:53:12.768753+00:00
[2022-09-09 00:53:15,418] {taskinstance.py:1889} ERROR - Task failed with exception
Traceback (most recent call last):
  File "/home/airflow/.local/lib/python3.7/site-packages/airflow/operators/python.py", line 171, in execute
    return_value = self.execute_callable()
  File "/home/airflow/.local/lib/python3.7/site-packages/airflow/operators/python.py", line 189, in execute_callable
    return self.python_callable(*self.op_args, **self.op_kwargs)
  File "/opt/airflow/dags/.ipynb_checkpoints/tcc_dag-checkpoint.py", line 53, in get_github_data
    for x in open("/usr/local/airflow/dags/repository.txt", "r"):
FileNotFoundError: [Errno 2] No such file or directory: '/usr/local/airflow/dags/repository.txt'
[2022-09-09 00:53:15,444] {taskinstance.py:1400} INFO - Marking task as FAILED. dag_id=tcc_dag, task_id=github-sca-data, execution_date=20220909T005312, start_date=20220909T005314, end_date=20220909T005315
[2022-09-09 00:53:15,473] {standard_task_runner.py:97} ERROR - Failed to execute job 134 for task github-sca-data ([Errno 2] No such file or directory: '/usr/local/airflow/dags/repository.txt'; 78)
[2022-09-09 00:53:15,495] {local_task_job.py:156} INFO - Task exited with return code 1
[2022-09-09 00:53:15,579] {local_task_job.py:273} INFO - 0 downstream tasks scheduled from follow-on schedule check
