[2022-09-12 01:52:22,425] {taskinstance.py:1159} INFO - Dependencies all met for <TaskInstance: tcc_dag.add-db-data manual__2022-09-12T01:52:10.915369+00:00 [queued]>
[2022-09-12 01:52:22,437] {taskinstance.py:1159} INFO - Dependencies all met for <TaskInstance: tcc_dag.add-db-data manual__2022-09-12T01:52:10.915369+00:00 [queued]>
[2022-09-12 01:52:22,438] {taskinstance.py:1356} INFO - 
--------------------------------------------------------------------------------
[2022-09-12 01:52:22,439] {taskinstance.py:1357} INFO - Starting attempt 1 of 1
[2022-09-12 01:52:22,440] {taskinstance.py:1358} INFO - 
--------------------------------------------------------------------------------
[2022-09-12 01:52:22,457] {taskinstance.py:1377} INFO - Executing <Task(PythonOperator): add-db-data> on 2022-09-12 01:52:10.915369+00:00
[2022-09-12 01:52:22,463] {standard_task_runner.py:52} INFO - Started process 13867 to run task
[2022-09-12 01:52:22,467] {standard_task_runner.py:79} INFO - Running: ['***', 'tasks', 'run', 'tcc_dag', 'add-db-data', 'manual__2022-09-12T01:52:10.915369+00:00', '--job-id', '592', '--raw', '--subdir', 'DAGS_FOLDER/.ipynb_checkpoints/tcc_dag-checkpoint.py', '--cfg-path', '/tmp/tmpj8r4sy9s', '--error-file', '/tmp/tmpla9irvfv']
[2022-09-12 01:52:22,468] {standard_task_runner.py:80} INFO - Job 592: Subtask add-db-data
[2022-09-12 01:52:22,538] {task_command.py:369} INFO - Running <TaskInstance: tcc_dag.add-db-data manual__2022-09-12T01:52:10.915369+00:00 [running]> on host b6ddae3e9f9e
[2022-09-12 01:52:22,614] {taskinstance.py:1571} INFO - Exporting the following env vars:
AIRFLOW_CTX_DAG_OWNER=Michelle Mesquita
AIRFLOW_CTX_DAG_ID=tcc_dag
AIRFLOW_CTX_TASK_ID=add-db-data
AIRFLOW_CTX_EXECUTION_DATE=2022-09-12T01:52:10.915369+00:00
AIRFLOW_CTX_TRY_NUMBER=1
AIRFLOW_CTX_DAG_RUN_ID=manual__2022-09-12T01:52:10.915369+00:00
[2022-09-12 01:52:22,617] {taskinstance.py:1889} ERROR - Task failed with exception
Traceback (most recent call last):
  File "/home/airflow/.local/lib/python3.7/site-packages/airflow/operators/python.py", line 171, in execute
    return_value = self.execute_callable()
  File "/home/airflow/.local/lib/python3.7/site-packages/airflow/operators/python.py", line 189, in execute_callable
    return self.python_callable(*self.op_args, **self.op_kwargs)
  File "/opt/airflow/dags/.ipynb_checkpoints/tcc_dag-checkpoint.py", line 98, in add_db_data
    df_current = pd.read_csv('./final_csv.csv', index_col=0, header=0)
  File "/home/airflow/.local/lib/python3.7/site-packages/pandas/util/_decorators.py", line 311, in wrapper
    return func(*args, **kwargs)
  File "/home/airflow/.local/lib/python3.7/site-packages/pandas/io/parsers/readers.py", line 586, in read_csv
    return _read(filepath_or_buffer, kwds)
  File "/home/airflow/.local/lib/python3.7/site-packages/pandas/io/parsers/readers.py", line 482, in _read
    parser = TextFileReader(filepath_or_buffer, **kwds)
  File "/home/airflow/.local/lib/python3.7/site-packages/pandas/io/parsers/readers.py", line 811, in __init__
    self._engine = self._make_engine(self.engine)
  File "/home/airflow/.local/lib/python3.7/site-packages/pandas/io/parsers/readers.py", line 1040, in _make_engine
    return mapping[engine](self.f, **self.options)  # type: ignore[call-arg]
  File "/home/airflow/.local/lib/python3.7/site-packages/pandas/io/parsers/c_parser_wrapper.py", line 51, in __init__
    self._open_handles(src, kwds)
  File "/home/airflow/.local/lib/python3.7/site-packages/pandas/io/parsers/base_parser.py", line 229, in _open_handles
    errors=kwds.get("encoding_errors", "strict"),
  File "/home/airflow/.local/lib/python3.7/site-packages/pandas/io/common.py", line 707, in get_handle
    newline="",
FileNotFoundError: [Errno 2] No such file or directory: './final_csv.csv'
[2022-09-12 01:52:22,631] {taskinstance.py:1400} INFO - Marking task as FAILED. dag_id=tcc_dag, task_id=add-db-data, execution_date=20220912T015210, start_date=20220912T015222, end_date=20220912T015222
[2022-09-12 01:52:22,642] {standard_task_runner.py:97} ERROR - Failed to execute job 592 for task add-db-data ([Errno 2] No such file or directory: './final_csv.csv'; 13867)
[2022-09-12 01:52:22,682] {local_task_job.py:156} INFO - Task exited with return code 1
[2022-09-12 01:52:22,727] {local_task_job.py:273} INFO - 0 downstream tasks scheduled from follow-on schedule check
