[2022-09-11 15:24:58,990] {taskinstance.py:1159} INFO - Dependencies all met for <TaskInstance: tcc_dag.add-db-data manual__2022-09-11T15:24:51.189592+00:00 [queued]>
[2022-09-11 15:24:59,006] {taskinstance.py:1159} INFO - Dependencies all met for <TaskInstance: tcc_dag.add-db-data manual__2022-09-11T15:24:51.189592+00:00 [queued]>
[2022-09-11 15:24:59,007] {taskinstance.py:1356} INFO - 
--------------------------------------------------------------------------------
[2022-09-11 15:24:59,009] {taskinstance.py:1357} INFO - Starting attempt 1 of 1
[2022-09-11 15:24:59,010] {taskinstance.py:1358} INFO - 
--------------------------------------------------------------------------------
[2022-09-11 15:24:59,034] {taskinstance.py:1377} INFO - Executing <Task(PythonOperator): add-db-data> on 2022-09-11 15:24:51.189592+00:00
[2022-09-11 15:24:59,041] {standard_task_runner.py:52} INFO - Started process 14996 to run task
[2022-09-11 15:24:59,046] {standard_task_runner.py:79} INFO - Running: ['***', 'tasks', 'run', 'tcc_dag', 'add-db-data', 'manual__2022-09-11T15:24:51.189592+00:00', '--job-id', '515', '--raw', '--subdir', 'DAGS_FOLDER/.ipynb_checkpoints/tcc_dag-checkpoint.py', '--cfg-path', '/tmp/tmp6p6ul47w', '--error-file', '/tmp/tmp37xid2t8']
[2022-09-11 15:24:59,048] {standard_task_runner.py:80} INFO - Job 515: Subtask add-db-data
[2022-09-11 15:24:59,137] {task_command.py:369} INFO - Running <TaskInstance: tcc_dag.add-db-data manual__2022-09-11T15:24:51.189592+00:00 [running]> on host b6ddae3e9f9e
[2022-09-11 15:24:59,272] {taskinstance.py:1571} INFO - Exporting the following env vars:
AIRFLOW_CTX_DAG_OWNER=Michelle Mesquita
AIRFLOW_CTX_DAG_ID=tcc_dag
AIRFLOW_CTX_TASK_ID=add-db-data
AIRFLOW_CTX_EXECUTION_DATE=2022-09-11T15:24:51.189592+00:00
AIRFLOW_CTX_TRY_NUMBER=1
AIRFLOW_CTX_DAG_RUN_ID=manual__2022-09-11T15:24:51.189592+00:00
[2022-09-11 15:25:24,515] {taskinstance.py:1889} ERROR - Task failed with exception
Traceback (most recent call last):
  File "/home/airflow/.local/lib/python3.7/site-packages/airflow/operators/python.py", line 171, in execute
    return_value = self.execute_callable()
  File "/home/airflow/.local/lib/python3.7/site-packages/airflow/operators/python.py", line 189, in execute_callable
    return self.python_callable(*self.op_args, **self.op_kwargs)
  File "/opt/airflow/dags/.ipynb_checkpoints/tcc_dag-checkpoint.py", line 97, in add_db_data
    df_diff = pd.concat([df_current,df_db]).drop_duplicates(subset=["ds_url_issue","id_vulnerability"],keep=False).reset_index()
  File "/home/airflow/.local/lib/python3.7/site-packages/pandas/util/_decorators.py", line 311, in wrapper
    return func(*args, **kwargs)
  File "/home/airflow/.local/lib/python3.7/site-packages/pandas/core/reshape/concat.py", line 304, in concat
    sort=sort,
  File "/home/airflow/.local/lib/python3.7/site-packages/pandas/core/reshape/concat.py", line 384, in __init__
    raise TypeError(msg)
TypeError: cannot concatenate object of type '<class 'list'>'; only Series and DataFrame objs are valid
[2022-09-11 15:25:24,537] {taskinstance.py:1400} INFO - Marking task as FAILED. dag_id=tcc_dag, task_id=add-db-data, execution_date=20220911T152451, start_date=20220911T152458, end_date=20220911T152524
[2022-09-11 15:25:24,561] {standard_task_runner.py:97} ERROR - Failed to execute job 515 for task add-db-data (cannot concatenate object of type '<class 'list'>'; only Series and DataFrame objs are valid; 14996)
[2022-09-11 15:25:24,608] {local_task_job.py:156} INFO - Task exited with return code 1
[2022-09-11 15:25:24,653] {local_task_job.py:273} INFO - 0 downstream tasks scheduled from follow-on schedule check
