[2022-09-09 01:31:31,144] {taskinstance.py:1159} INFO - Dependencies all met for <TaskInstance: tcc_dag.generate-csv-data manual__2022-09-09T01:30:47.886981+00:00 [queued]>
[2022-09-09 01:31:31,157] {taskinstance.py:1159} INFO - Dependencies all met for <TaskInstance: tcc_dag.generate-csv-data manual__2022-09-09T01:30:47.886981+00:00 [queued]>
[2022-09-09 01:31:31,158] {taskinstance.py:1356} INFO - 
--------------------------------------------------------------------------------
[2022-09-09 01:31:31,159] {taskinstance.py:1357} INFO - Starting attempt 1 of 1
[2022-09-09 01:31:31,161] {taskinstance.py:1358} INFO - 
--------------------------------------------------------------------------------
[2022-09-09 01:31:31,195] {taskinstance.py:1377} INFO - Executing <Task(PythonOperator): generate-csv-data> on 2022-09-09 01:30:47.886981+00:00
[2022-09-09 01:31:31,210] {standard_task_runner.py:52} INFO - Started process 103 to run task
[2022-09-09 01:31:31,214] {standard_task_runner.py:79} INFO - Running: ['***', 'tasks', 'run', 'tcc_dag', 'generate-csv-data', 'manual__2022-09-09T01:30:47.886981+00:00', '--job-id', '375', '--raw', '--subdir', 'DAGS_FOLDER/.ipynb_checkpoints/tcc_dag-checkpoint.py', '--cfg-path', '/tmp/tmpta0xb2tg', '--error-file', '/tmp/tmp76fzh1dv']
[2022-09-09 01:31:31,219] {standard_task_runner.py:80} INFO - Job 375: Subtask generate-csv-data
[2022-09-09 01:31:31,616] {task_command.py:369} INFO - Running <TaskInstance: tcc_dag.generate-csv-data manual__2022-09-09T01:30:47.886981+00:00 [running]> on host b6ddae3e9f9e
[2022-09-09 01:31:31,838] {taskinstance.py:1571} INFO - Exporting the following env vars:
AIRFLOW_CTX_DAG_OWNER=Michelle Mesquita
AIRFLOW_CTX_DAG_ID=tcc_dag
AIRFLOW_CTX_TASK_ID=generate-csv-data
AIRFLOW_CTX_EXECUTION_DATE=2022-09-09T01:30:47.886981+00:00
AIRFLOW_CTX_TRY_NUMBER=1
AIRFLOW_CTX_DAG_RUN_ID=manual__2022-09-09T01:30:47.886981+00:00
[2022-09-09 01:31:31,844] {taskinstance.py:1889} ERROR - Task failed with exception
Traceback (most recent call last):
  File "/home/airflow/.local/lib/python3.7/site-packages/airflow/operators/python.py", line 171, in execute
    return_value = self.execute_callable()
  File "/home/airflow/.local/lib/python3.7/site-packages/airflow/operators/python.py", line 189, in execute_callable
    return self.python_callable(*self.op_args, **self.op_kwargs)
  File "/opt/airflow/dags/.ipynb_checkpoints/tcc_dag-checkpoint.py", line 75, in generate_csv_data
    df = pd.concat(li, axis=0, ignore_index=True)
  File "/home/airflow/.local/lib/python3.7/site-packages/pandas/util/_decorators.py", line 311, in wrapper
    return func(*args, **kwargs)
  File "/home/airflow/.local/lib/python3.7/site-packages/pandas/core/reshape/concat.py", line 304, in concat
    sort=sort,
  File "/home/airflow/.local/lib/python3.7/site-packages/pandas/core/reshape/concat.py", line 351, in __init__
    raise ValueError("No objects to concatenate")
ValueError: No objects to concatenate
[2022-09-09 01:31:31,870] {taskinstance.py:1400} INFO - Marking task as FAILED. dag_id=tcc_dag, task_id=generate-csv-data, execution_date=20220909T013047, start_date=20220909T013131, end_date=20220909T013131
[2022-09-09 01:31:31,894] {standard_task_runner.py:97} ERROR - Failed to execute job 375 for task generate-csv-data (No objects to concatenate; 103)
[2022-09-09 01:31:31,945] {local_task_job.py:156} INFO - Task exited with return code 1
[2022-09-09 01:31:32,033] {local_task_job.py:273} INFO - 0 downstream tasks scheduled from follow-on schedule check
