[2022-09-08 23:40:31,585] {taskinstance.py:1159} INFO - Dependencies all met for <TaskInstance: tcc_dag.github-sca-data manual__2022-09-08T23:40:29.421110+00:00 [queued]>
[2022-09-08 23:40:31,624] {taskinstance.py:1159} INFO - Dependencies all met for <TaskInstance: tcc_dag.github-sca-data manual__2022-09-08T23:40:29.421110+00:00 [queued]>
[2022-09-08 23:40:31,626] {taskinstance.py:1356} INFO - 
--------------------------------------------------------------------------------
[2022-09-08 23:40:31,627] {taskinstance.py:1357} INFO - Starting attempt 1 of 1
[2022-09-08 23:40:31,628] {taskinstance.py:1358} INFO - 
--------------------------------------------------------------------------------
[2022-09-08 23:40:31,697] {taskinstance.py:1377} INFO - Executing <Task(PythonOperator): github-sca-data> on 2022-09-08 23:40:29.421110+00:00
[2022-09-08 23:40:31,710] {standard_task_runner.py:52} INFO - Started process 84 to run task
[2022-09-08 23:40:31,768] {standard_task_runner.py:79} INFO - Running: ['***', 'tasks', 'run', 'tcc_dag', 'github-sca-data', 'manual__2022-09-08T23:40:29.421110+00:00', '--job-id', '125', '--raw', '--subdir', 'DAGS_FOLDER/.ipynb_checkpoints/tcc_dag-checkpoint.py', '--cfg-path', '/tmp/tmp1gs_joaw', '--error-file', '/tmp/tmpf0pf5t0s']
[2022-09-08 23:40:31,771] {standard_task_runner.py:80} INFO - Job 125: Subtask github-sca-data
[2022-09-08 23:40:32,060] {task_command.py:369} INFO - Running <TaskInstance: tcc_dag.github-sca-data manual__2022-09-08T23:40:29.421110+00:00 [running]> on host 9a5942a886e3
[2022-09-08 23:40:32,419] {taskinstance.py:1571} INFO - Exporting the following env vars:
AIRFLOW_CTX_DAG_OWNER=Michelle Mesquita
AIRFLOW_CTX_DAG_ID=tcc_dag
AIRFLOW_CTX_TASK_ID=github-sca-data
AIRFLOW_CTX_EXECUTION_DATE=2022-09-08T23:40:29.421110+00:00
AIRFLOW_CTX_TRY_NUMBER=1
AIRFLOW_CTX_DAG_RUN_ID=manual__2022-09-08T23:40:29.421110+00:00
[2022-09-08 23:40:32,432] {taskinstance.py:1889} ERROR - Task failed with exception
Traceback (most recent call last):
  File "/home/airflow/.local/lib/python3.7/site-packages/airflow/operators/python.py", line 171, in execute
    return_value = self.execute_callable()
  File "/home/airflow/.local/lib/python3.7/site-packages/airflow/operators/python.py", line 189, in execute_callable
    return self.python_callable(*self.op_args, **self.op_kwargs)
  File "/opt/airflow/dags/.ipynb_checkpoints/tcc_dag-checkpoint.py", line 53, in get_github_data
    for x in open("/Users/mac/Desktop/TCC-IGTI/airflow-local/dags/repository.txt", "r"):
FileNotFoundError: [Errno 2] No such file or directory: '/Users/mac/Desktop/TCC-IGTI/airflow-local/dags/repository.txt'
[2022-09-08 23:40:32,453] {taskinstance.py:1400} INFO - Marking task as FAILED. dag_id=tcc_dag, task_id=github-sca-data, execution_date=20220908T234029, start_date=20220908T234031, end_date=20220908T234032
[2022-09-08 23:40:32,519] {standard_task_runner.py:97} ERROR - Failed to execute job 125 for task github-sca-data ([Errno 2] No such file or directory: '/Users/mac/Desktop/TCC-IGTI/airflow-local/dags/repository.txt'; 84)
[2022-09-08 23:40:32,592] {local_task_job.py:156} INFO - Task exited with return code 1
[2022-09-08 23:40:32,837] {local_task_job.py:273} INFO - 0 downstream tasks scheduled from follow-on schedule check
